2021-12-01 02:11:37.246844: (404, "Not found: '/static/phantich-background.jpg'")
2021-12-01 02:12:20.853182: (404, "Not found: '/static/phantich-background.jpg'")
2021-12-01 02:12:22.523028: (404, "Not found: '/static/phantich-background.jpg'")
2021-12-01 02:12:23.128800: (404, "Not found: '/static/phantich-background.jpg'")
2021-12-01 02:12:23.674195: (404, "Not found: '/static/phantich-background.jpg'")
2021-12-01 02:12:24.507484: (404, "Not found: '/static/phantich-background.jpg'")
2021-12-01 15:06:16.163389: (404, "Not found: '/static/phantich-background.jpg'")
2021-12-01 15:06:18.739414: (404, "Not found: '/static/phantich-background.jpg'")
2021-12-01 15:06:19.209887: (404, "Not found: '/static/phantich-background.jpg'")
2021-12-01 15:06:19.685473: (404, "Not found: '/static/phantich-background.jpg'")
2021-12-02 09:59:01.979309: (404, "Not found: '/static/phantich-background.jpg'")
2021-12-02 09:59:03.591693: (404, "Not found: '/static/phantich-background.jpg'")
2021-12-02 09:59:04.097032: (404, "Not found: '/static/phantich-background.jpg'")
2021-12-02 09:59:04.469612: (404, "Not found: '/static/phantich-background.jpg'")
2021-12-02 09:59:04.806099: (404, "Not found: '/static/phantich-background.jpg'")
2021-12-03 01:46:14.316252: (404, "Not found: '/static/phantich-background.jpg'")
2021-12-03 16:09:05.289805: (500, 'Internal Server Error', FileNotFoundError(2, 'No such file or directory'), 'Traceback (most recent call last):\n  File "/home/JakeClark/.virtualenvs/myenv/lib/python3.8/site-packages/bottle.py", line 868, in _handle\n    return route.call(**args)\n  File "/home/JakeClark/.virtualenvs/myenv/lib/python3.8/site-packages/bottle.py", line 1748, in wrapper\n    rv = callback(*a, **ka)\n  File "/home/JakeClark/api.py", line 37, in load\n    def load(file):\n  File "/home/JakeClark/api.py", line 16, in load_file\n    def load_file(file):\nFileNotFoundError: [Errno 2] No such file or directory: \'index2.html\'\n')
2021-12-03 16:09:41.069565: (404, 'Not found: index2.html')
2021-12-12 16:09:45.116028: (500, 'Internal Server Error', NameError("name 'all_html' is not defined"), 'Traceback (most recent call last):\n  File "/home/JakeClark/.virtualenvs/myenv/lib/python3.8/site-packages/bottle.py", line 868, in _handle\n    return route.call(**args)\n  File "/home/JakeClark/.virtualenvs/myenv/lib/python3.8/site-packages/bottle.py", line 1748, in wrapper\n    rv = callback(*a, **ka)\n  File "/home/JakeClark/api.py", line 92, in load\n    if file not in all_html:\nNameError: name \'all_html\' is not defined\n')
2021-12-12 16:12:28.476459: (500, 'Internal Server Error', ProgrammingError(-1, 'Not all parameters were used in the SQL statement', None), 'Traceback (most recent call last):\n  File "/home/JakeClark/.virtualenvs/myenv/lib/python3.8/site-packages/bottle.py", line 868, in _handle\n    return route.call(**args)\n  File "/home/JakeClark/.virtualenvs/myenv/lib/python3.8/site-packages/bottle.py", line 1748, in wrapper\n    rv = callback(*a, **ka)\n  File "/home/JakeClark/api.py", line 117, in result\n    c.execute("SELECT EXISTS(SELECT * FROM answer_collection WHERE ans=?)",(ids,))\n  File "/home/JakeClark/.virtualenvs/myenv/lib/python3.8/site-packages/mysql/connector/cursor_cext.py", line 266, in execute\n    raise errors.ProgrammingError(\nmysql.connector.errors.ProgrammingError: Not all parameters were used in the SQL statement\n')
2021-12-12 16:15:12.652426: (404, "Not found: '/result?id=t4BWii'")
2021-12-12 16:18:05.266538: (500, 'Internal Server Error', ProgrammingError(1146, "1146 (42S02): Table 'JakeClark$default.answer_collection_new' doesn't exist", '42S02'), 'Traceback (most recent call last):\n  File "/home/JakeClark/.virtualenvs/myenv/lib/python3.8/site-packages/mysql/connector/connection_cext.py", line 517, in cmd_query\n    self._cmysql.query(query,\n_mysql_connector.MySQLInterfaceError: Table \'JakeClark$default.answer_collection_new\' doesn\'t exist\n\nDuring handling of the above exception, another exception occurred:\n\nTraceback (most recent call last):\n  File "/home/JakeClark/.virtualenvs/myenv/lib/python3.8/site-packages/bottle.py", line 868, in _handle\n    return route.call(**args)\n  File "/home/JakeClark/.virtualenvs/myenv/lib/python3.8/site-packages/bottle.py", line 1748, in wrapper\n    rv = callback(*a, **ka)\n  File "/home/JakeClark/api.py", line 109, in result\n    data = process_data(ids)\n  File "/home/JakeClark/api.py", line 55, in process_data\n    data = receive_data(num)\n  File "/home/JakeClark/api.py", line 45, in receive_data\n    c.execute("SELECT ques1, ques2, ques3, ques4, ques5 FROM answer_collection_new WHERE ans=%s",(num,))\n  File "/home/JakeClark/.virtualenvs/myenv/lib/python3.8/site-packages/mysql/connector/cursor_cext.py", line 270, in execute\n    result = self._cnx.cmd_query(stmt, raw=self._raw,\n  File "/home/JakeClark/.virtualenvs/myenv/lib/python3.8/site-packages/mysql/connector/connection_cext.py", line 522, in cmd_query\n    raise errors.get_mysql_exception(exc.errno, msg=exc.msg,\nmysql.connector.errors.ProgrammingError: 1146 (42S02): Table \'JakeClark$default.answer_collection_new\' doesn\'t exist\n')
2021-12-12 16:18:25.574827: (500, 'Internal Server Error', DataError(1136, "1136 (21S01): Column count doesn't match value count at row 1", '21S01'), 'Traceback (most recent call last):\n  File "/home/JakeClark/.virtualenvs/myenv/lib/python3.8/site-packages/mysql/connector/connection_cext.py", line 517, in cmd_query\n    self._cmysql.query(query,\n_mysql_connector.MySQLInterfaceError: Column count doesn\'t match value count at row 1\n\nDuring handling of the above exception, another exception occurred:\n\nTraceback (most recent call last):\n  File "/home/JakeClark/.virtualenvs/myenv/lib/python3.8/site-packages/bottle.py", line 868, in _handle\n    return route.call(**args)\n  File "/home/JakeClark/.virtualenvs/myenv/lib/python3.8/site-packages/bottle.py", line 1748, in wrapper\n    rv = callback(*a, **ka)\n  File "/home/JakeClark/api.py", line 137, in collect_answer\n    c.execute("INSERT INTO answer_collection (ques1, ques2, ques3, ques4, ques5) VALUES (%s, %s, %s, %s, %s, %s)", (\n  File "/home/JakeClark/.virtualenvs/myenv/lib/python3.8/site-packages/mysql/connector/cursor_cext.py", line 270, in execute\n    result = self._cnx.cmd_query(stmt, raw=self._raw,\n  File "/home/JakeClark/.virtualenvs/myenv/lib/python3.8/site-packages/mysql/connector/connection_cext.py", line 522, in cmd_query\n    raise errors.get_mysql_exception(exc.errno, msg=exc.msg,\nmysql.connector.errors.DataError: 1136 (21S01): Column count doesn\'t match value count at row 1\n')
2021-12-12 16:21:21.100495: (500, 'Internal Server Error', ProgrammingError(1146, "1146 (42S02): Table 'JakeClark$default.answer_collection_new' doesn't exist", '42S02'), 'Traceback (most recent call last):\n  File "/home/JakeClark/.virtualenvs/myenv/lib/python3.8/site-packages/mysql/connector/connection_cext.py", line 517, in cmd_query\n    self._cmysql.query(query,\n_mysql_connector.MySQLInterfaceError: Table \'JakeClark$default.answer_collection_new\' doesn\'t exist\n\nDuring handling of the above exception, another exception occurred:\n\nTraceback (most recent call last):\n  File "/home/JakeClark/.virtualenvs/myenv/lib/python3.8/site-packages/bottle.py", line 868, in _handle\n    return route.call(**args)\n  File "/home/JakeClark/.virtualenvs/myenv/lib/python3.8/site-packages/bottle.py", line 1748, in wrapper\n    rv = callback(*a, **ka)\n  File "/home/JakeClark/api.py", line 109, in result\n  File "/home/JakeClark/api.py", line 55, in process_data\n    data = receive_data(num)\n  File "/home/JakeClark/api.py", line 45, in receive_data\n    c.execute("SELECT ques1, ques2, ques3, ques4, ques5 FROM answer_collection WHERE ans=%s",(num,))\n  File "/home/JakeClark/.virtualenvs/myenv/lib/python3.8/site-packages/mysql/connector/cursor_cext.py", line 270, in execute\n    result = self._cnx.cmd_query(stmt, raw=self._raw,\n  File "/home/JakeClark/.virtualenvs/myenv/lib/python3.8/site-packages/mysql/connector/connection_cext.py", line 522, in cmd_query\n    raise errors.get_mysql_exception(exc.errno, msg=exc.msg,\nmysql.connector.errors.ProgrammingError: 1146 (42S02): Table \'JakeClark$default.answer_collection_new\' doesn\'t exist\n')
2021-12-12 16:21:56.314961: (500, 'Internal Server Error', TypeError("'NoneType' object is not subscriptable"), 'Traceback (most recent call last):\n  File "/home/JakeClark/.virtualenvs/myenv/lib/python3.8/site-packages/bottle.py", line 868, in _handle\n    return route.call(**args)\n  File "/home/JakeClark/.virtualenvs/myenv/lib/python3.8/site-packages/bottle.py", line 1748, in wrapper\n    rv = callback(*a, **ka)\n  File "/home/JakeClark/api.py", line 110, in result\n    data = process_data(ids)\n  File "/home/JakeClark/api.py", line 61, in process_data\n    user_answer = data[i]\nTypeError: \'NoneType\' object is not subscriptable\n')
2021-12-12 16:41:19.205970: (500, 'Internal Server Error', TypeError("'NoneType' object is not subscriptable"), 'Traceback (most recent call last):\n  File "/home/JakeClark/.virtualenvs/myenv/lib/python3.8/site-packages/bottle.py", line 868, in _handle\n    return route.call(**args)\n  File "/home/JakeClark/.virtualenvs/myenv/lib/python3.8/site-packages/bottle.py", line 1748, in wrapper\n    rv = callback(*a, **ka)\n  File "/home/JakeClark/api.py", line 110, in result\n    conn = mysql.connector.connect(\n  File "/home/JakeClark/api.py", line 61, in process_data\n    user_answer = data[i]\nTypeError: \'NoneType\' object is not subscriptable\n')
2021-12-12 16:41:47.837958: (500, 'Internal Server Error', TypeError("'NoneType' object is not subscriptable"), 'Traceback (most recent call last):\n  File "/home/JakeClark/.virtualenvs/myenv/lib/python3.8/site-packages/bottle.py", line 868, in _handle\n    return route.call(**args)\n  File "/home/JakeClark/.virtualenvs/myenv/lib/python3.8/site-packages/bottle.py", line 1748, in wrapper\n    rv = callback(*a, **ka)\n  File "/home/JakeClark/api.py", line 110, in result\n    conn = mysql.connector.connect(\n  File "/home/JakeClark/api.py", line 61, in process_data\n    user_answer = data[i]\nTypeError: \'NoneType\' object is not subscriptable\n')
2021-12-12 16:42:44.429333: (500, 'Internal Server Error', TypeError("'NoneType' object is not subscriptable"), 'Traceback (most recent call last):\n  File "/home/JakeClark/.virtualenvs/myenv/lib/python3.8/site-packages/bottle.py", line 868, in _handle\n    return route.call(**args)\n  File "/home/JakeClark/.virtualenvs/myenv/lib/python3.8/site-packages/bottle.py", line 1748, in wrapper\n    rv = callback(*a, **ka)\n  File "/home/JakeClark/api.py", line 110, in result\n    conn = mysql.connector.connect(\n  File "/home/JakeClark/api.py", line 61, in process_data\n    user_answer = data[i]\nTypeError: \'NoneType\' object is not subscriptable\n')
2021-12-12 16:43:05.897408: (500, 'Internal Server Error', TypeError("'NoneType' object is not subscriptable"), 'Traceback (most recent call last):\n  File "/home/JakeClark/.virtualenvs/myenv/lib/python3.8/site-packages/bottle.py", line 868, in _handle\n    return route.call(**args)\n  File "/home/JakeClark/.virtualenvs/myenv/lib/python3.8/site-packages/bottle.py", line 1748, in wrapper\n    rv = callback(*a, **ka)\n  File "/home/JakeClark/api.py", line 110, in result\n    conn = mysql.connector.connect(\n  File "/home/JakeClark/api.py", line 61, in process_data\n    user_answer = data[i]\nTypeError: \'NoneType\' object is not subscriptable\n')
2021-12-12 16:45:55.890096: (500, 'Internal Server Error', IntegrityError(1062, "1062 (23000): Duplicate entry '4' for key 'PRIMARY'", '23000'), 'Traceback (most recent call last):\n  File "/home/JakeClark/.virtualenvs/myenv/lib/python3.8/site-packages/mysql/connector/connection_cext.py", line 517, in cmd_query\n    self._cmysql.query(query,\n_mysql_connector.MySQLInterfaceError: Duplicate entry \'4\' for key \'PRIMARY\'\n\nDuring handling of the above exception, another exception occurred:\n\nTraceback (most recent call last):\n  File "/home/JakeClark/.virtualenvs/myenv/lib/python3.8/site-packages/bottle.py", line 868, in _handle\n    return route.call(**args)\n  File "/home/JakeClark/.virtualenvs/myenv/lib/python3.8/site-packages/bottle.py", line 1748, in wrapper\n    rv = callback(*a, **ka)\n  File "/home/JakeClark/api.py", line 138, in collect_answer\n    def collect_answer():\n  File "/home/JakeClark/.virtualenvs/myenv/lib/python3.8/site-packages/mysql/connector/cursor_cext.py", line 270, in execute\n    result = self._cnx.cmd_query(stmt, raw=self._raw,\n  File "/home/JakeClark/.virtualenvs/myenv/lib/python3.8/site-packages/mysql/connector/connection_cext.py", line 522, in cmd_query\n    raise errors.get_mysql_exception(exc.errno, msg=exc.msg,\nmysql.connector.errors.IntegrityError: 1062 (23000): Duplicate entry \'4\' for key \'PRIMARY\'\n')
2021-12-12 16:47:54.458412: (404, "Not found: '/static/Giải pháp.png'")
2021-12-12 16:47:55.999623: (404, "Not found: '/static/Giải pháp.png'")
2021-12-12 16:48:24.932698: (404, "Not found: '/static/Giải pháp.png'")
2021-12-12 16:48:26.154087: (404, "Not found: '/static/Giải pháp.png'")
2021-12-12 16:48:33.576659: (404, "Not found: '/static/Giải pháp.png'")
2021-12-12 16:48:34.225613: (404, "Not found: '/static/Giải pháp.png'")
2021-12-12 16:48:49.366150: (404, "Not found: '/static/Giải pháp.png'")
2021-12-12 16:48:50.489509: (404, "Not found: '/static/Giải pháp.png'")
2021-12-30 15:13:19.999104: (500, 'Internal Server Error', IndexError('tuple index out of range'), 'Traceback (most recent call last):\n  File "/home/JakeClark/.virtualenvs/myenv/lib/python3.8/site-packages/bottle.py", line 868, in _handle\n    return route.call(**args)\n  File "/home/JakeClark/.virtualenvs/myenv/lib/python3.8/site-packages/bottle.py", line 1748, in wrapper\n    rv = callback(*a, **ka)\n  File "/home/JakeClark/api.py", line 189, in show_admin\n    return template("toxic-positivity-admin", full=full, summary=summary)\n  File "/home/JakeClark/.virtualenvs/myenv/lib/python3.8/site-packages/bottle.py", line 3630, in template\n    return TEMPLATES[tplid].render(kwargs)\n  File "/home/JakeClark/.virtualenvs/myenv/lib/python3.8/site-packages/bottle.py", line 3419, in render\n    self.execute(stdout, env)\n  File "/home/JakeClark/.virtualenvs/myenv/lib/python3.8/site-packages/bottle.py", line 3406, in execute\n    eval(self.co, env)\n  File "/home/JakeClark/toxic-positivity-admin.tpl", line 21, in <module>\n    <td>{{summary[i][j]}}</td>\nIndexError: tuple index out of range\n')
2021-12-30 15:15:11.044268: (500, 'Internal Server Error', InternalError(-1, 'Unread result found', None), 'Traceback (most recent call last):\n  File "/home/JakeClark/.virtualenvs/myenv/lib/python3.8/site-packages/bottle.py", line 868, in _handle\n    return route.call(**args)\n  File "/home/JakeClark/.virtualenvs/myenv/lib/python3.8/site-packages/bottle.py", line 1748, in wrapper\n    rv = callback(*a, **ka)\n  File "/home/JakeClark/api.py", line 181, in show_admin\n    c.execute(f"SELECT total FROM {i}")\n  File "/home/JakeClark/.virtualenvs/myenv/lib/python3.8/site-packages/mysql/connector/cursor_cext.py", line 244, in execute\n    self._cnx.handle_unread_result()\n  File "/home/JakeClark/.virtualenvs/myenv/lib/python3.8/site-packages/mysql/connector/connection_cext.py", line 786, in handle_unread_result\n    raise errors.InternalError("Unread result found")\nmysql.connector.errors.InternalError: Unread result found\n')
2021-12-30 15:15:29.437180: (500, 'Internal Server Error', InternalError(-1, 'Unread result found', None), 'Traceback (most recent call last):\n  File "/home/JakeClark/.virtualenvs/myenv/lib/python3.8/site-packages/bottle.py", line 868, in _handle\n    return route.call(**args)\n  File "/home/JakeClark/.virtualenvs/myenv/lib/python3.8/site-packages/bottle.py", line 1748, in wrapper\n    rv = callback(*a, **ka)\n  File "/home/JakeClark/api.py", line 181, in show_admin\n    c.execute(f"SELECT total FROM {i}")\n  File "/home/JakeClark/.virtualenvs/myenv/lib/python3.8/site-packages/mysql/connector/cursor_cext.py", line 244, in execute\n    self._cnx.handle_unread_result()\n  File "/home/JakeClark/.virtualenvs/myenv/lib/python3.8/site-packages/mysql/connector/connection_cext.py", line 786, in handle_unread_result\n    raise errors.InternalError("Unread result found")\nmysql.connector.errors.InternalError: Unread result found\n')
2021-12-30 15:19:18.319453: (500, 'Internal Server Error', IndexError('tuple index out of range'), 'Traceback (most recent call last):\n  File "/home/JakeClark/.virtualenvs/myenv/lib/python3.8/site-packages/bottle.py", line 868, in _handle\n    return route.call(**args)\n  File "/home/JakeClark/.virtualenvs/myenv/lib/python3.8/site-packages/bottle.py", line 1748, in wrapper\n    rv = callback(*a, **ka)\n  File "/home/JakeClark/api.py", line 189, in show_admin\n    return template("toxic-positivity-admin", full=full, summary=summary)\n  File "/home/JakeClark/.virtualenvs/myenv/lib/python3.8/site-packages/bottle.py", line 3630, in template\n    return TEMPLATES[tplid].render(kwargs)\n  File "/home/JakeClark/.virtualenvs/myenv/lib/python3.8/site-packages/bottle.py", line 3419, in render\n    self.execute(stdout, env)\n  File "/home/JakeClark/.virtualenvs/myenv/lib/python3.8/site-packages/bottle.py", line 3406, in execute\n    eval(self.co, env)\n  File "/home/JakeClark/toxic-positivity-admin.tpl", line 21, in <module>\n    <td>{{summary[i][j]}}</td>\nIndexError: tuple index out of range\n')
2021-12-31 12:29:30.226221: (500, 'Internal Server Error', TypeError("'list' object is not callable"), 'Traceback (most recent call last):\n  File "/home/JakeClark/.virtualenvs/myenv/lib/python3.8/site-packages/bottle.py", line 868, in _handle\n    return route.call(**args)\n  File "/home/JakeClark/.virtualenvs/myenv/lib/python3.8/site-packages/bottle.py", line 1748, in wrapper\n    rv = callback(*a, **ka)\n  File "/home/JakeClark/api.py", line 189, in show_admin\n    return template("toxic-positivity-admin", full=full, summary=summary)\n  File "/home/JakeClark/.virtualenvs/myenv/lib/python3.8/site-packages/bottle.py", line 3630, in template\n    return TEMPLATES[tplid].render(kwargs)\n  File "/home/JakeClark/.virtualenvs/myenv/lib/python3.8/site-packages/bottle.py", line 3419, in render\n    self.execute(stdout, env)\n  File "/home/JakeClark/.virtualenvs/myenv/lib/python3.8/site-packages/bottle.py", line 3406, in execute\n    eval(self.co, env)\n  File "/home/JakeClark/toxic-positivity-admin.tpl", line 42, in <module>\n    <td><a href="/result?id={{full[i][len(full(id))-1]}}">{{full[i][len(full(id))-1]}}</td>\nTypeError: \'list\' object is not callable\n')
2022-01-01 04:04:25.260312: (404, "Not found: '/static/home-img.jpg'")
2022-01-04 06:03:55.864065: (404, "Not found: '/title-font.otf'")
2022-01-04 06:03:55.882137: (404, "Not found: '/para-font.otf'")
2022-01-06 15:43:29.557548: (404, "Not found: '/title-font.otf'")
2022-01-06 15:43:29.907562: (404, "Not found: '/para-font.otf'")
2022-01-07 12:29:12.767538: (500, 'Internal Server Error', ValueError('not enough values to unpack (expected 5, got 4)'), 'Traceback (most recent call last):\n  File "/home/JakeClark/.virtualenvs/myenv/lib/python3.8/site-packages/bottle.py", line 868, in _handle\n    return route.call(**args)\n  File "/home/JakeClark/.virtualenvs/myenv/lib/python3.8/site-packages/bottle.py", line 1748, in wrapper\n    rv = callback(*a, **ka)\n  File "/home/JakeClark/api.py", line 198, in show_admin\n    for ques_num, a_count, b_count, c_count, d_count in summary:\nValueError: not enough values to unpack (expected 5, got 4)\n')
2022-01-07 12:42:53.661141: (500, 'Internal Server Error', TypeError('can only concatenate str (not "int") to str'), 'Traceback (most recent call last):\n  File "/home/JakeClark/.virtualenvs/myenv/lib/python3.8/site-packages/bottle.py", line 868, in _handle\n    return route.call(**args)\n  File "/home/JakeClark/.virtualenvs/myenv/lib/python3.8/site-packages/bottle.py", line 1748, in wrapper\n    rv = callback(*a, **ka)\n  File "/home/JakeClark/api.py", line 205, in show_admin\n    full_worksheet.write(row, i+1, "Câu hỏi "+i+1)\nTypeError: can only concatenate str (not "int") to str\n')
2022-01-07 12:43:46.246993: (500, 'Internal Server Error', TypeError('can only concatenate str (not "int") to str'), 'Traceback (most recent call last):\n  File "/home/JakeClark/.virtualenvs/myenv/lib/python3.8/site-packages/bottle.py", line 868, in _handle\n    return route.call(**args)\n  File "/home/JakeClark/.virtualenvs/myenv/lib/python3.8/site-packages/bottle.py", line 1748, in wrapper\n    rv = callback(*a, **ka)\n  File "/home/JakeClark/api.py", line 205, in show_admin\n    full_worksheet.write(row, i+1, f"Câu hỏi {i+1}")\nTypeError: can only concatenate str (not "int") to str\n')
2022-01-07 12:44:20.591520: (500, 'Internal Server Error', TypeError('can only concatenate str (not "int") to str'), 'Traceback (most recent call last):\n  File "/home/JakeClark/.virtualenvs/myenv/lib/python3.8/site-packages/bottle.py", line 868, in _handle\n    return route.call(**args)\n  File "/home/JakeClark/.virtualenvs/myenv/lib/python3.8/site-packages/bottle.py", line 1748, in wrapper\n    rv = callback(*a, **ka)\n  File "/home/JakeClark/api.py", line 205, in show_admin\n    full_worksheet.write(row, i+1, f"Câu hỏi {str(i+1)}")\nTypeError: can only concatenate str (not "int") to str\n')
2022-01-07 12:45:18.847531: (500, 'Internal Server Error', TypeError('can only concatenate str (not "int") to str'), 'Traceback (most recent call last):\n  File "/home/JakeClark/.virtualenvs/myenv/lib/python3.8/site-packages/bottle.py", line 868, in _handle\n    return route.call(**args)\n  File "/home/JakeClark/.virtualenvs/myenv/lib/python3.8/site-packages/bottle.py", line 1748, in wrapper\n    rv = callback(*a, **ka)\n  File "/home/JakeClark/api.py", line 205, in show_admin\n    full_worksheet.write(row, i+1, "Câu hỏi "+str(i+1))\nTypeError: can only concatenate str (not "int") to str\n')
2022-01-07 12:52:47.003497: (500, 'Internal Server Error', FileCreateError(FileNotFoundError(2, 'No such file or directory')), 'Traceback (most recent call last):\n  File "/home/JakeClark/.virtualenvs/myenv/lib/python3.8/site-packages/xlsxwriter/workbook.py", line 324, in close\n    self._store_workbook()\n  File "/home/JakeClark/.virtualenvs/myenv/lib/python3.8/site-packages/xlsxwriter/workbook.py", line 659, in _store_workbook\n    raise e\n  File "/home/JakeClark/.virtualenvs/myenv/lib/python3.8/site-packages/xlsxwriter/workbook.py", line 656, in _store_workbook\n    xlsx_file = ZipFile(self.filename, "w", compression=ZIP_DEFLATED,\n  File "/usr/lib/python3.8/zipfile.py", line 1251, in __init__\n    self.fp = io.open(file, filemode)\nFileNotFoundError: [Errno 2] No such file or directory: \'./excel-file/full_07/01/2022_12:52:46.xlsx\'\n\nDuring handling of the above exception, another exception occurred:\n\nTraceback (most recent call last):\n  File "/home/JakeClark/.virtualenvs/myenv/lib/python3.8/site-packages/bottle.py", line 868, in _handle\n    return route.call(**args)\n  File "/home/JakeClark/.virtualenvs/myenv/lib/python3.8/site-packages/bottle.py", line 1748, in wrapper\n    rv = callback(*a, **ka)\n  File "/home/JakeClark/api.py", line 215, in show_admin\n    workbook.close()\n  File "/home/JakeClark/.virtualenvs/myenv/lib/python3.8/site-packages/xlsxwriter/workbook.py", line 326, in close\n    raise FileCreateError(e)\nxlsxwriter.exceptions.FileCreateError: [Errno 2] No such file or directory: \'./excel-file/full_07/01/2022_12:52:46.xlsx\'\n')
2022-01-07 13:12:54.975857: (404, "Not found: '/toxic-positivity-admin/full_07-01-2022_20-12-52.xlsx'")
2022-01-07 13:13:39.323397: (404, "Not found: '/toxic-positivity-admin/full_07-01-2022_20-13-37.xlsx'")
2022-01-07 13:14:21.630715: (404, "Not found: '/toxic-positivity-admin/full_07-01-2022_20-13-37.xlsx'")
2022-01-07 13:14:21.940547: (404, "Not found: '/toxic-positivity-admin/static/style.css'")
2022-01-07 13:14:21.977601: (404, "Not found: '/toxic-positivity-admin/static/404-error.jpg'")
2022-01-07 13:15:12.814486: (404, "Not found: '/toxic-positivity-admin/full_07-01-2022_20-15-10.xlsx'")
2022-01-07 13:16:12.574381: (404, "Not found: '/toxic-positivity-admin/full_07-01-2022_20-15-10.xlsx'")
2022-01-07 13:16:12.928740: (404, "Not found: '/toxic-positivity-admin/static/style.css'")
2022-01-07 13:16:12.947162: (404, "Not found: '/toxic-positivity-admin/static/404-error.jpg'")
2022-01-07 13:18:29.398871: (404, "Not found: '/toxic-positivity-admin/full_07-01-2022_20-15-10.xlsx'")
2022-01-07 13:18:29.710706: (404, "Not found: '/toxic-positivity-admin/static/404-error.jpg'")
2022-01-07 13:18:29.715616: (404, "Not found: '/toxic-positivity-admin/static/style.css'")
2022-01-11 23:08:46.214764: (404, "Not found: '/robots.txt'")
2022-01-18 08:40:34.043040: (404, "Not found: '/robots.txt'")
